WARNING    - 2025-06-02 10:45:52,149 - client          : PyNaCl is not installed, voice will NOT be supported
INFO       - 2025-06-02 10:45:52,155 - client          : logging in using static token
INFO       - 2025-06-02 10:45:53,417 - main            : Loaded (distance_sensor.py)
INFO       - 2025-06-02 10:45:53,417 - main            : Loaded (hello.py)
INFO       - 2025-06-02 10:45:53,417 - main            : Loaded (image.py)
INFO       - 2025-06-02 10:45:53,417 - main            : Loaded (light.py)
INFO       - 2025-06-02 10:45:53,434 - main            : Loaded (temphum.py)
INFO       - 2025-06-02 10:45:54,102 - main            : Synced 11 commands to global
INFO       - 2025-06-02 10:45:54,892 - gateway         : Shard ID None has connected to Gateway (Session ID: 293f4bce2d417efcf99b51243bc2b8ac).
WARNING    - 2025-06-02 11:25:58,743 - gateway         : Can't keep up, shard ID None websocket is 10.2s behind.
WARNING    - 2025-06-02 11:25:58,968 - gateway         : Can't keep up, shard ID None websocket is 10.5s behind.
ERROR      - 2025-06-02 11:40:46,380 - client          : Attempting a reconnect in 0.78s
Traceback (most recent call last):
  File "D:\TJN_EGG-INC\venv\lib\site-packages\aiohttp\connector.py", line 1335, in _create_direct_connection
    hosts = await self._resolve_host(host, port, traces=traces)
  File "D:\TJN_EGG-INC\venv\lib\site-packages\aiohttp\connector.py", line 989, in _resolve_host
    return await asyncio.shield(resolved_host_task)
  File "D:\TJN_EGG-INC\venv\lib\site-packages\aiohttp\connector.py", line 1020, in _resolve_host_with_throttle
    addrs = await self._resolver.resolve(host, port, family=self._family)
  File "D:\TJN_EGG-INC\venv\lib\site-packages\aiohttp\resolver.py", line 38, in resolve
    infos = await self._loop.getaddrinfo(
  File "C:\Users\marve\AppData\Local\Programs\Python\Python38\lib\asyncio\base_events.py", line 825, in getaddrinfo
    return await self.run_in_executor(
  File "C:\Users\marve\AppData\Local\Programs\Python\Python38\lib\concurrent\futures\thread.py", line 57, in run
    result = self.fn(*self.args, **self.kwargs)
  File "C:\Users\marve\AppData\Local\Programs\Python\Python38\lib\socket.py", line 918, in getaddrinfo
    for res in _socket.getaddrinfo(host, port, family, type, proto, flags):
socket.gaierror: [Errno 11004] getaddrinfo failed

The above exception was the direct cause of the following exception:

Traceback (most recent call last):
  File "D:\TJN_EGG-INC\venv\lib\site-packages\discord\client.py", line 701, in connect
    self.ws = await asyncio.wait_for(coro, timeout=60.0)
  File "C:\Users\marve\AppData\Local\Programs\Python\Python38\lib\asyncio\tasks.py", line 494, in wait_for
    return fut.result()
  File "D:\TJN_EGG-INC\venv\lib\site-packages\discord\gateway.py", line 375, in from_client
    socket = await client.http.ws_connect(str(url))
  File "D:\TJN_EGG-INC\venv\lib\site-packages\discord\http.py", line 554, in ws_connect
    return await self.__session.ws_connect(url, **kwargs)
  File "D:\TJN_EGG-INC\venv\lib\site-packages\aiohttp\client.py", line 938, in _ws_connect
    resp = await self.request(
  File "D:\TJN_EGG-INC\venv\lib\site-packages\aiohttp\client.py", line 663, in _request
    conn = await self._connector.connect(
  File "D:\TJN_EGG-INC\venv\lib\site-packages\aiohttp\connector.py", line 538, in connect
    proto = await self._create_connection(req, traces, timeout)
  File "D:\TJN_EGG-INC\venv\lib\site-packages\aiohttp\connector.py", line 1050, in _create_connection
    _, proto = await self._create_direct_connection(req, traces, timeout)
  File "D:\TJN_EGG-INC\venv\lib\site-packages\aiohttp\connector.py", line 1341, in _create_direct_connection
    raise ClientConnectorDNSError(req.connection_key, exc) from exc
aiohttp.client_exceptions.ClientConnectorDNSError: Cannot connect to host gateway-us-east1-b.discord.gg:443 ssl:default [getaddrinfo failed]
ERROR      - 2025-06-02 11:40:49,790 - client          : Attempting a reconnect in 1.51s
Traceback (most recent call last):
  File "D:\TJN_EGG-INC\venv\lib\site-packages\aiohttp\connector.py", line 1335, in _create_direct_connection
    hosts = await self._resolve_host(host, port, traces=traces)
  File "D:\TJN_EGG-INC\venv\lib\site-packages\aiohttp\connector.py", line 989, in _resolve_host
    return await asyncio.shield(resolved_host_task)
  File "D:\TJN_EGG-INC\venv\lib\site-packages\aiohttp\connector.py", line 1020, in _resolve_host_with_throttle
    addrs = await self._resolver.resolve(host, port, family=self._family)
  File "D:\TJN_EGG-INC\venv\lib\site-packages\aiohttp\resolver.py", line 38, in resolve
    infos = await self._loop.getaddrinfo(
  File "C:\Users\marve\AppData\Local\Programs\Python\Python38\lib\asyncio\base_events.py", line 825, in getaddrinfo
    return await self.run_in_executor(
  File "C:\Users\marve\AppData\Local\Programs\Python\Python38\lib\concurrent\futures\thread.py", line 57, in run
    result = self.fn(*self.args, **self.kwargs)
  File "C:\Users\marve\AppData\Local\Programs\Python\Python38\lib\socket.py", line 918, in getaddrinfo
    for res in _socket.getaddrinfo(host, port, family, type, proto, flags):
socket.gaierror: [Errno 11004] getaddrinfo failed

The above exception was the direct cause of the following exception:

Traceback (most recent call last):
  File "D:\TJN_EGG-INC\venv\lib\site-packages\discord\client.py", line 701, in connect
    self.ws = await asyncio.wait_for(coro, timeout=60.0)
  File "C:\Users\marve\AppData\Local\Programs\Python\Python38\lib\asyncio\tasks.py", line 494, in wait_for
    return fut.result()
  File "D:\TJN_EGG-INC\venv\lib\site-packages\discord\gateway.py", line 375, in from_client
    socket = await client.http.ws_connect(str(url))
  File "D:\TJN_EGG-INC\venv\lib\site-packages\discord\http.py", line 554, in ws_connect
    return await self.__session.ws_connect(url, **kwargs)
  File "D:\TJN_EGG-INC\venv\lib\site-packages\aiohttp\client.py", line 938, in _ws_connect
    resp = await self.request(
  File "D:\TJN_EGG-INC\venv\lib\site-packages\aiohttp\client.py", line 663, in _request
    conn = await self._connector.connect(
  File "D:\TJN_EGG-INC\venv\lib\site-packages\aiohttp\connector.py", line 538, in connect
    proto = await self._create_connection(req, traces, timeout)
  File "D:\TJN_EGG-INC\venv\lib\site-packages\aiohttp\connector.py", line 1050, in _create_connection
    _, proto = await self._create_direct_connection(req, traces, timeout)
  File "D:\TJN_EGG-INC\venv\lib\site-packages\aiohttp\connector.py", line 1341, in _create_direct_connection
    raise ClientConnectorDNSError(req.connection_key, exc) from exc
aiohttp.client_exceptions.ClientConnectorDNSError: Cannot connect to host gateway-us-east1-b.discord.gg:443 ssl:default [getaddrinfo failed]
ERROR      - 2025-06-02 11:40:51,542 - client          : Attempting a reconnect in 6.00s
Traceback (most recent call last):
  File "D:\TJN_EGG-INC\venv\lib\site-packages\aiohttp\connector.py", line 1335, in _create_direct_connection
    hosts = await self._resolve_host(host, port, traces=traces)
  File "D:\TJN_EGG-INC\venv\lib\site-packages\aiohttp\connector.py", line 989, in _resolve_host
    return await asyncio.shield(resolved_host_task)
  File "D:\TJN_EGG-INC\venv\lib\site-packages\aiohttp\connector.py", line 1020, in _resolve_host_with_throttle
    addrs = await self._resolver.resolve(host, port, family=self._family)
  File "D:\TJN_EGG-INC\venv\lib\site-packages\aiohttp\resolver.py", line 38, in resolve
    infos = await self._loop.getaddrinfo(
  File "C:\Users\marve\AppData\Local\Programs\Python\Python38\lib\asyncio\base_events.py", line 825, in getaddrinfo
    return await self.run_in_executor(
  File "C:\Users\marve\AppData\Local\Programs\Python\Python38\lib\concurrent\futures\thread.py", line 57, in run
    result = self.fn(*self.args, **self.kwargs)
  File "C:\Users\marve\AppData\Local\Programs\Python\Python38\lib\socket.py", line 918, in getaddrinfo
    for res in _socket.getaddrinfo(host, port, family, type, proto, flags):
socket.gaierror: [Errno 11004] getaddrinfo failed

The above exception was the direct cause of the following exception:

Traceback (most recent call last):
  File "D:\TJN_EGG-INC\venv\lib\site-packages\discord\client.py", line 701, in connect
    self.ws = await asyncio.wait_for(coro, timeout=60.0)
  File "C:\Users\marve\AppData\Local\Programs\Python\Python38\lib\asyncio\tasks.py", line 494, in wait_for
    return fut.result()
  File "D:\TJN_EGG-INC\venv\lib\site-packages\discord\gateway.py", line 375, in from_client
    socket = await client.http.ws_connect(str(url))
  File "D:\TJN_EGG-INC\venv\lib\site-packages\discord\http.py", line 554, in ws_connect
    return await self.__session.ws_connect(url, **kwargs)
  File "D:\TJN_EGG-INC\venv\lib\site-packages\aiohttp\client.py", line 938, in _ws_connect
    resp = await self.request(
  File "D:\TJN_EGG-INC\venv\lib\site-packages\aiohttp\client.py", line 663, in _request
    conn = await self._connector.connect(
  File "D:\TJN_EGG-INC\venv\lib\site-packages\aiohttp\connector.py", line 538, in connect
    proto = await self._create_connection(req, traces, timeout)
  File "D:\TJN_EGG-INC\venv\lib\site-packages\aiohttp\connector.py", line 1050, in _create_connection
    _, proto = await self._create_direct_connection(req, traces, timeout)
  File "D:\TJN_EGG-INC\venv\lib\site-packages\aiohttp\connector.py", line 1341, in _create_direct_connection
    raise ClientConnectorDNSError(req.connection_key, exc) from exc
aiohttp.client_exceptions.ClientConnectorDNSError: Cannot connect to host gateway-us-east1-b.discord.gg:443 ssl:default [getaddrinfo failed]
INFO       - 2025-06-02 11:41:00,843 - gateway         : Shard ID None has successfully RESUMED session 293f4bce2d417efcf99b51243bc2b8ac.
